<?xml version="1.0"?>
<robot name="printerArm">

  <link name="world" />
  <joint name="world_fixed" type="fixed">
    <origin xyz="0 0 0" rpy="0 0 0" />
    <parent link="world" />
    <child link="base_link" />
  </joint>

  <link name="base_link">
    <inertial>
      <mass value="10.985" />
      <inertia ixx="1e-3" ixy="0.0" ixz="0.0" iyy="1e-3" iyz="0.0" izz="1e-3" />
    </inertial>
    <visual>
      <geometry>
        <cylinder length="0.2" radius="0.2" />
      </geometry>
    </visual>
  </link>

  <joint name="joint1" type="revolute">
    <parent link="base_link" />
    <child link="link1" />
    <origin rpy="0 0 0" xyz="0 0 0.1" />
    <axis xyz="0 0 1" />
    <limit effort="411" lower="-6.2832" upper="6.2832" velocity="3.1416" />
    <!-- <dynamics damping="60.0" friction="4.0" /> -->
  </joint>

  <link name="link1">
    <inertial>
      <mass value="5" />
      <inertia ixx="1e-3" ixy="0.0" ixz="0.0" iyy="1e-3" iyz="0.0" izz="1e-3" />
    </inertial>
    <visual>
      <geometry>
        <cylinder length="0.6" radius="0.05" />
      </geometry>
      <origin rpy="0 0 0" xyz="0 0 0.3" />
      <!-- <material name="white"/> -->
    </visual>
  </link>

  <joint name="joint2" type="revolute">
    <parent link="link1" />
    <child link="link2" />
    <origin rpy="0 0 0" xyz="0 0 0.6" />
    <axis xyz="0 1 0" />
    <limit effort="411" lower="-6.2832" upper="6.2832" velocity="3.1416" />
    <!-- <dynamics damping="60.0" friction="4.0" /> -->
  </joint>

  <link name="link2">
    <inertial>
      <mass value="5" />
      <inertia ixx="1e-3" ixy="0.0" ixz="0.0" iyy="1e-3" iyz="0.0" izz="1e-3" />
    </inertial>
    <visual>
      <geometry>
        <cylinder length="0.6" radius="0.025" />
      </geometry>
      <origin rpy="0 0 0" xyz="0 0 0.3" />
      <!-- <material name="green"/> -->
    </visual>
  </link>

  <joint name="joint3" type="revolute">
    <parent link="link2" />
    <child link="link3" />
    <origin rpy="0 0 0" xyz="0 0 0.6" />
    <axis xyz="0 1 0" />
    <limit effort="411" lower="-6.2832" upper="6.2832" velocity="3.1416" />
    <!-- <dynamics damping="60.0" friction="4.0" /> -->
  </joint>

  <link name="link3">
    <inertial>
      <mass value="5" />
      <inertia ixx="1e-3" ixy="0.0" ixz="0.0" iyy="1e-3" iyz="0.0" izz="1e-3" />
    </inertial>
    <visual>
      <geometry>
        <cylinder length="0.4" radius="0.05" />
      </geometry>
      <origin rpy="0 0 0" xyz="0 0 0.2" />
      <!-- <material name="blue"/> -->
    </visual>
  </link>

  <joint name="joint4" type="revolute">
    <parent link="link3" />
    <child link="link4" />
    <origin rpy="0 0 0" xyz="0 0 0.4" />
    <axis xyz="0 1 0" />
    <limit effort="411" lower="-6.2832" upper="6.2832" velocity="3.1416" />
    <!-- <dynamics damping="60.0" friction="4.0" /> -->
  </joint>

  <link name="link4">
    <inertial>
      <mass value="5" />
      <inertia ixx="1e-3" ixy="0.0" ixz="0.0" iyy="1e-3" iyz="0.0" izz="1e-3" />
    </inertial>
    <visual>
      <geometry>
        <cylinder length="0.2" radius="0.025" />
      </geometry>
      <origin rpy="0 0 0" xyz="0 0 0.1" />
      <!-- <material name="yellow"/> -->
    </visual>
  </link>

  <plugin
    filename="ignition-gazebo-joint-state-publisher-system"
    name="ignition::gazebo::systems::JointStatePublisher">
  </plugin>

</robot>