<?xml version="1.0"?>
<sdf version="1.6">
    <world name="empty">
        <physics name="1ms" type="ignored">
            <max_step_size>0.001</max_step_size>
            <real_time_factor>1.0</real_time_factor>
        </physics>
        <plugin filename="gz-sim-physics-system" name="gz::sim::systems::Physics"></plugin>
        <plugin filename="gz-sim-user-commands-system"
            name="gz::sim::systems::UserCommands"></plugin>
        <plugin filename="gz-sim-scene-broadcaster-system"
            name="gz::sim::systems::SceneBroadcaster"></plugin>
        <plugin filename="gz-sim-contact-system" name="gz::sim::systems::Contact"></plugin>

        <light type="directional" name="sun">
            <cast_shadows>true</cast_shadows>
            <pose>0 0 10 0 0 0</pose>
            <diffuse>0.8 0.8 0.8 1</diffuse>
            <specular>0.2 0.2 0.2 1</specular>
            <attenuation>
                <range>1000</range>
                <constant>0.9</constant>
                <linear>0.01</linear>
                <quadratic>0.001</quadratic>
            </attenuation>
            <direction>-0.5 0.1 -0.9</direction>
        </light>

        <model name="ground_plane">
            <static>true</static>
            <link name="link">
                <collision name="collision">
                    <geometry>
                        <plane>
                            <normal>0 0 1</normal>
                            <size>100 100</size>
                        </plane>
                    </geometry>
                </collision>
                <visual name="visual">
                    <geometry>
                        <plane>
                            <normal>0 0 1</normal>
                            <size>100 100</size>
                        </plane>
                    </geometry>
                    <material>
                        <ambient>0.8 0.8 0.8 1</ambient>
                        <diffuse>0.8 0.8 0.8 1</diffuse>
                        <specular>0.8 0.8 0.8 1</specular>
                    </material>
                </visual>
            </link>
        </model>

        <model name="printerArm">
            <pose>0 0 0.05 0 0 0</pose>
            <link name="base_link">
                <collision name='base_link_collision_0'>
                    <laser_retro>0</laser_retro>
                    <max_contacts>10</max_contacts>
                    <pose>0 0 0 0 -0 0</pose>
                    <geometry>
                        <cylinder>
                            <radius>0.5</radius>
                            <length>0.1</length>
                        </cylinder>
                    </geometry>
                </collision>
                <collision name="base_link_collision_1">
                    <geometry>
                        <sphere>
                            <radius>0.15</radius>
                        </sphere>
                    </geometry>
                </collision>
                <visual name='base_link_visual_0'>
                    <pose>0 0 0 0 0 0</pose>
                    <geometry>
                        <cylinder>
                            <radius>0.5</radius>
                            <length>0.1</length>
                        </cylinder>
                    </geometry>
                    <material>
                        <ambient>0.5 0.5 0.5 1</ambient>
                        <diffuse>0.8 0.8 0.8 1</diffuse>
                        <specular>0.8 0.8 0.8 1</specular>
                    </material>
                    <transparency>0</transparency>
                    <cast_shadows>1</cast_shadows>
                </visual>
                <visual name="base_link_visual_1">
                    <pose> 0 0 0.1 0 0 0</pose>
                    <geometry>
                        <sphere>
                            <radius>0.15</radius>
                        </sphere>
                    </geometry>
                    <material>
                        <ambient>0.5 0.5 0.5 1</ambient>
                        <diffuse>0.8 0.8 0.8 1</diffuse>
                        <specular>0.8 0.8 0.8 1</specular>
                    </material>
                    <transparency>0.5</transparency>
                </visual>
                <inertial>
                    <mass>10000000000</mass>
                    <inertia>
                        <ixx>0.0003358</ixx>
                        <iyy>0.0003358</iyy>
                        <izz>0.000005</izz>
                    </inertia>
                </inertial>
            </link>

            <link name="link1">
                <pose relative_to="joint1">0 0 0.2 0 0 0</pose>
                <collision name="link1_collision_0">
                    <geometry>
                        <cylinder>
                            <radius>0.1</radius>
                            <length>0.5</length>
                        </cylinder>
                    </geometry>
                </collision>
                <collision name="link1_collision_1">
                    <geometry>
                        <sphere>
                            <radius>0.15</radius>
                        </sphere>
                    </geometry>
                </collision>
                <visual name="link1_visual_0">
                    <geometry>
                        <cylinder>
                            <radius>0.1</radius>
                            <length>0.5</length>
                        </cylinder>
                    </geometry>
                    <material>
                        <ambient>0.5 0 0 1</ambient>
                        <diffuse>0.8 0 0 1</diffuse>
                        <specular>0.8 0 0 1</specular>
                    </material>
                </visual>
                <visual name="link1_visual_1">
                    <pose relative_to="joint1">0 0 0.25 0 0 0</pose>
                    <geometry>
                        <sphere>
                            <radius>0.15</radius>
                        </sphere>
                    </geometry>
                    <material>
                        <ambient>0.5 0.5 0.5 1</ambient>
                        <diffuse>0.8 0.8 0.8 1</diffuse>
                        <specular>0.8 0.8 0.8 1</specular>
                    </material>
                    <transparency>0.5</transparency>
                </visual>
                <inertial>
                    <mass>0.1</mass>
                    <inertia>
                        <ixx>0.0003358</ixx>
                        <iyy>0.0003358</iyy>
                        <izz>0.000005</izz>
                    </inertia>
                </inertial>
            </link>

            <link name="link2">
                <pose relative_to="joint2">0 0 0.5 0 0 0</pose>
                <collision name="link2_collision_0">
                    <geometry>
                        <cylinder>
                            <radius>0.1</radius>
                            <length>1</length>
                        </cylinder>
                    </geometry>
                </collision>
                <collision name="link2_collision_1">
                    <geometry>
                        <sphere>
                            <radius>0.15</radius>
                        </sphere>
                    </geometry>
                </collision>
                <visual name="link2_visual_0">
                    <geometry>
                        <cylinder>
                            <radius>0.1</radius>
                            <length>1</length>
                        </cylinder>
                    </geometry>
                    <material>
                        <ambient>0.5 0 0 1</ambient>
                        <diffuse>0.8 0 0 1</diffuse>
                        <specular>0.8 0 0 1</specular>
                    </material>
                </visual>
                <visual name="link2_visual_1">
                    <pose relative_to="joint2">0 0 1 0 0 0</pose>
                    <geometry>
                        <sphere>
                            <radius>0.15</radius>
                        </sphere>
                    </geometry>
                    <material>
                        <ambient>0.5 0.5 0.5 1</ambient>
                        <diffuse>0.8 0.8 0.8 1</diffuse>
                        <specular>0.8 0.8 0.8 1</specular>
                    </material>
                    <transparency>0.5</transparency>
                </visual>
                <inertial>
                    <mass>0.1</mass>
                    <inertia>
                        <ixx>0.0003358</ixx>
                        <iyy>0.0003358</iyy>
                        <izz>0.000005</izz>
                    </inertia>
                </inertial>
            </link>

            <link name="link3">
                <pose relative_to="joint3">0 0 0.4 0 0 0</pose>
                <collision name="link3_collision_0">
                    <geometry>
                        <cylinder>
                            <radius>0.1</radius>
                            <length>0.8</length>
                        </cylinder>
                    </geometry>
                </collision>
                <collision name="link3_collision_1">
                    <geometry>
                        <sphere>
                            <radius>0.15</radius>
                        </sphere>
                    </geometry>
                </collision>
                <visual name="link3_visual_0">
                    <geometry>
                        <cylinder>
                            <radius>0.1</radius>
                            <length>0.8</length>
                        </cylinder>
                    </geometry>
                    <material>
                        <ambient>0.5 0 0 1</ambient>
                        <diffuse>0.8 0 0 1</diffuse>
                        <specular>0.8 0 0 1</specular>
                    </material>
                </visual>
                <visual name="link3_visual_1">
                    <pose relative_to="joint3">0 0 0.8 0 0 0</pose>
                    <geometry>
                        <sphere>
                            <radius>0.15</radius>
                        </sphere>
                    </geometry>
                    <material>
                        <ambient>0.5 0.5 0.5 1</ambient>
                        <diffuse>0.8 0.8 0.8 1</diffuse>
                        <specular>0.8 0.8 0.8 1</specular>
                    </material>
                    <transparency>0.5</transparency>
                </visual>
                <inertial>
                    <mass>0.1</mass>
                    <inertia>
                        <ixx>0.0003358</ixx>
                        <iyy>0.0003358</iyy>
                        <izz>0.000005</izz>
                    </inertia>
                </inertial>
            </link>

            <link name="link4">
                <pose relative_to="joint4">0 0 0.25 0 0 0</pose>
                <collision name="link4_collision_1">
                    <geometry>
                        <sphere>
                            <radius>0.15</radius>
                        </sphere>
                    </geometry>
                </collision>
                <visual name="link4_visual_1">
                    <pose relative_to="joint4">0 0 0 0 0 0</pose>
                    <geometry>
                        <sphere>
                            <radius>0.15</radius>
                        </sphere>
                    </geometry>
                    <material>
                        <ambient>0.5 0.5 0.5 1</ambient>
                        <diffuse>0.8 0.8 0.8 1</diffuse>
                        <specular>0.8 0.8 0.8 1</specular>
                    </material>
                    <transparency>1</transparency>
                </visual>
                <inertial>
                    <mass>0.1</mass>
                    <inertia>
                        <ixx>0.0003358</ixx>
                        <iyy>0.0003358</iyy>
                        <izz>0.000005</izz>
                    </inertia>
                </inertial>
            </link>

            <link name="link5">
                <pose relative_to="joint5">0 0 0 0 0 0</pose>
                <collision name="link3_collision_0">
                    <geometry>
                        <cylinder>
                            <radius>0.1</radius>
                            <length>0.5</length>
                        </cylinder>
                    </geometry>
                </collision>
                <collision name="link3_collision_1">
                    <geometry>
                        <sphere>
                            <radius>0.15</radius>
                        </sphere>
                    </geometry>
                </collision>
                <visual name="link3_visual_0">
                    <geometry>
                        <cylinder>
                            <radius>0.1</radius>
                            <length>0.5</length>
                        </cylinder>
                    </geometry>
                    <material>
                        <ambient>0.5 0 0 1</ambient>
                        <diffuse>0.8 0 0 1</diffuse>
                        <specular>0.8 0 0 1</specular>
                    </material>
                </visual>
                <visual name="link3_visual_1">
                    <pose relative_to="joint5">0 0 0 0 0 0</pose>
                    <geometry>
                        <sphere>
                            <radius>0.15</radius>
                        </sphere>
                    </geometry>
                    <material>
                        <ambient>0.5 0.5 0.5 1</ambient>
                        <diffuse>0.8 0.8 0.8 1</diffuse>
                        <specular>0.8 0.8 0.8 1</specular>
                    </material>
                    <transparency>0.5</transparency>
                </visual>
                <inertial>
                    <mass>0.1</mass>
                    <inertia>
                        <ixx>0.0003358</ixx>
                        <iyy>0.0003358</iyy>
                        <izz>0.000005</izz>
                    </inertia>
                </inertial>
            </link>

            <link name="link6">
                <pose relative_to="joint6">0 0 0.05 0 0 0</pose>
                <collision name="link3_collision_0">
                    <geometry>
                        <cylinder>
                            <radius>0.01</radius>
                            <length>0.1</length>
                        </cylinder>
                    </geometry>
                </collision>
                <visual name="link3_visual_0">
                    <geometry>
                        <cylinder>
                            <radius>0.01</radius>
                            <length>0.1</length>
                        </cylinder>
                    </geometry>
                    <material>
                        <ambient>0.5 0 0 1</ambient>
                        <diffuse>0.8 0 0 1</diffuse>
                        <specular>0.8 0 0 1</specular>
                    </material>
                </visual>
                <inertial>
                    <mass>0.1</mass>
                    <inertia>
                        <ixx>0.0003358</ixx>
                        <iyy>0.0003358</iyy>
                        <izz>0.000005</izz>
                    </inertia>
                </inertial>
            </link>

            <joint name="joint1" type="revolute">
                <pose relative_to="base_link">0 0 0.1 0 0 0</pose>
                <parent>base_link</parent>
                <child>link1</child>
                <axis>
                    <xyz>0 0 1</xyz>
                    <dynamics>
                        <damping>0.5</damping>
                    </dynamics>
                </axis>
            </joint>

            <joint name="joint2" type="revolute">
                <pose relative_to="link1">0 0 0.25 0 0 0</pose>
                <parent>link1</parent>
                <child>link2</child>
                <axis>
                    <xyz>1 0 0</xyz>
                    <dynamics>
                        <damping>0.5</damping>
                    </dynamics>
                </axis>
            </joint>

            <joint name="joint3" type="revolute">
                <pose relative_to="link2">0 0 0.5 0 0 0</pose>
                <parent>link2</parent>
                <child>link3</child>
                <axis>
                    <xyz>1 0 0</xyz>
                    <dynamics>
                        <damping>0.5</damping>
                    </dynamics>
                </axis>
            </joint>

            <joint name="joint4" type="revolute">
                <pose relative_to="link3">0 0 0.4 0 0 0</pose>
                <parent>link3</parent>
                <child>link4</child>
                <axis>
                    <xyz>1 0 0</xyz>
                    <dynamics>
                        <damping>0.5</damping>
                    </dynamics>
                </axis>
            </joint>

            <joint name="joint5" type="revolute">
                <pose relative_to="link4">0 0 0 0 0 0</pose>
                <parent>link4</parent>
                <child>link5</child>
                <axis>
                    <xyz>0 0 1</xyz>
                    <dynamics>
                        <damping>0.5</damping>
                    </dynamics>
                </axis>
            </joint>

            <joint name="joint6" type="revolute">
                <pose relative_to="link4">0 0 0.25 0 0 0</pose>
                <parent>link5</parent>
                <child>link6</child>
                <axis>
                    <xyz>1 0 0</xyz>
                    <dynamics>
                        <damping>0.5</damping>
                    </dynamics>
                </axis>
            </joint>

            <plugin
                filename="gz-sim-joint-trajectory-controller-system"
                name="gz::sim::systems::JointTrajectoryController">
                <joint_name>joint1</joint_name>
                <initial_position>0</initial_position>
                <position_p_gain>300</position_p_gain>
                <position_i_gain>0.5</position_i_gain>
                <position_d_gain>0.5</position_d_gain>
                <position_i_min>-1</position_i_min>
                <position_i_max>1</position_i_max>
                <position_cmd_min>-20</position_cmd_min>
                <position_cmd_max>20</position_cmd_max>

                <joint_name>joint2</joint_name>
                <initial_position>0</initial_position>
                <position_p_gain>300</position_p_gain>
                <position_i_gain>0.2</position_i_gain>
                <position_d_gain>0.5</position_d_gain>
                <position_i_min>-1</position_i_min>
                <position_i_max>1</position_i_max>
                <position_cmd_min>-10</position_cmd_min>
                <position_cmd_max>10</position_cmd_max>

                <joint_name>joint3</joint_name>
                <initial_position>0</initial_position>
                <position_p_gain>300</position_p_gain>
                <position_i_gain>0.2</position_i_gain>
                <position_d_gain>0.5</position_d_gain>
                <position_i_min>-1</position_i_min>
                <position_i_max>1</position_i_max>
                <position_cmd_min>-10</position_cmd_min>
                <position_cmd_max>10</position_cmd_max>

                <joint_name>joint4</joint_name>
                <initial_position>0</initial_position>
                <position_p_gain>300</position_p_gain>
                <position_i_gain>0.2</position_i_gain>
                <position_d_gain>0.5</position_d_gain>
                <position_i_min>-1</position_i_min>
                <position_i_max>1</position_i_max>
                <position_cmd_min>-10</position_cmd_min>
                <position_cmd_max>10</position_cmd_max>

                <joint_name>joint5</joint_name>
                <initial_position>0</initial_position>
                <position_p_gain>300</position_p_gain>
                <position_i_gain>0.2</position_i_gain>
                <position_d_gain>0.5</position_d_gain>
                <position_i_min>-1</position_i_min>
                <position_i_max>1</position_i_max>
                <position_cmd_min>-10</position_cmd_min>
                <position_cmd_max>10</position_cmd_max>

                <joint_name>joint6</joint_name>
                <initial_position>0</initial_position>
                <position_p_gain>300</position_p_gain>
                <position_i_gain>0.2</position_i_gain>
                <position_d_gain>0.5</position_d_gain>
                <position_i_min>-1</position_i_min>
                <position_i_max>1</position_i_max>
                <position_cmd_min>-10</position_cmd_min>
                <position_cmd_max>10</position_cmd_max>
            </plugin>

        </model>

    </world>
</sdf>